Searching 1 file for ".exception"

Unable to open /Users/Root1/app/*
0 matches across 0 files


Searching 17190 files for ".exception"

/Users/Root1/app/app/emails.py:
   13  			mail.send(msg)
   14  	except Exception, e:
   15: 		app.logger.exception(e)
   16  
   17  def send_email(subject, sender, recipients, text_body, html_body):
   ..
   48  		user_id = s.loads(activation_slug)
   49  	except BadSignature:
   50: 		app.logger.exception(error)
   51  		abort(404)
   52  	send_email("Password Reset",
   ..
  115  		driver_id = s.loads(activation_slug)
  116  	except BadSignature:
  117: 		app.logger.exception(error)
  118  		abort(404)
  119  

/Users/Root1/app/app/frontend/backend/plugins/bootstrap-paginator/css/highlight.js/zenburn.css:
   44  pre .dos .flow,
   45  pre .diff .change,
   46: pre .python .exception,
   47  pre .python .built_in,
   48  pre .literal,

/Users/Root1/app/app/frontend/backend/plugins/gmaps/test/lib/jasmine.css:
   20  #HTMLReporter .symbolSummary li.pending { line-height: 11px; }
   21  #HTMLReporter .symbolSummary li.pending:before { color: #aaaaaa; content: "-"; }
   22: #HTMLReporter .exceptions { color: #fff; float: right; margin-top: 5px; margin-right: 5px; }
   23  #HTMLReporter .bar { line-height: 28px; font-size: 14px; display: block; color: #eee; }
   24  #HTMLReporter .runningAlert { background-color: #666666; }

/Users/Root1/app/app/frontend/frontend/plugins/gmaps/test/lib/jasmine.css:
   20  #HTMLReporter .symbolSummary li.pending { line-height: 11px; }
   21  #HTMLReporter .symbolSummary li.pending:before { color: #aaaaaa; content: "-"; }
   22: #HTMLReporter .exceptions { color: #fff; float: right; margin-top: 5px; margin-right: 5px; }
   23  #HTMLReporter .bar { line-height: 28px; font-size: 14px; display: block; color: #eee; }
   24  #HTMLReporter .runningAlert { background-color: #666666; }

/Users/Root1/app/app/frontend/plugins/bootstrap-paginator/css/highlight.js/zenburn.css:
   44  pre .dos .flow,
   45  pre .diff .change,
   46: pre .python .exception,
   47  pre .python .built_in,
   48  pre .literal,

/Users/Root1/app/app/frontend/plugins/gmaps/test/lib/jasmine.css:
   20  #HTMLReporter .symbolSummary li.pending { line-height: 11px; }
   21  #HTMLReporter .symbolSummary li.pending:before { color: #aaaaaa; content: "-"; }
   22: #HTMLReporter .exceptions { color: #fff; float: right; margin-top: 5px; margin-right: 5px; }
   23  #HTMLReporter .bar { line-height: 28px; font-size: 14px; display: block; color: #eee; }
   24  #HTMLReporter .runningAlert { background-color: #666666; }

/Users/Root1/app/app/static/backend/plugins/bootstrap-paginator/css/highlight.js/zenburn.css:
   44  pre .dos .flow,
   45  pre .diff .change,
   46: pre .python .exception,
   47  pre .python .built_in,
   48  pre .literal,

/Users/Root1/app/app/static/backend/plugins/gmaps/test/lib/jasmine.css:
   20  #HTMLReporter .symbolSummary li.pending { line-height: 11px; }
   21  #HTMLReporter .symbolSummary li.pending:before { color: #aaaaaa; content: "-"; }
   22: #HTMLReporter .exceptions { color: #fff; float: right; margin-top: 5px; margin-right: 5px; }
   23  #HTMLReporter .bar { line-height: 28px; font-size: 14px; display: block; color: #eee; }
   24  #HTMLReporter .runningAlert { background-color: #666666; }

/Users/Root1/app/app/static/frontend/plugins/gmaps/test/lib/jasmine.css:
   20  #HTMLReporter .symbolSummary li.pending { line-height: 11px; }
   21  #HTMLReporter .symbolSummary li.pending:before { color: #aaaaaa; content: "-"; }
   22: #HTMLReporter .exceptions { color: #fff; float: right; margin-top: 5px; margin-right: 5px; }
   23  #HTMLReporter .bar { line-height: 28px; font-size: 14px; display: block; color: #eee; }
   24  #HTMLReporter .runningAlert { background-color: #666666; }

/Users/Root1/app/app/views/auth.py:
  200  @app.errorhandler(403)
  201  def forbidden_error(error):
  202: 	app.logger.exception(error)
  203  	return render_template('static/404.html'), 403
  204  
  205  @app.errorhandler(404)
  206  def not_found_error(error):
  207: 	app.logger.exception(error)
  208  	return render_template('static/404.html'), 404
  209  

/Users/Root1/app/app/views/drivers.py:
  156  @app.errorhandler(403)
  157  def forbidden_error(error):
  158: 	app.logger.exception(error)
  159  	return render_template('static/404.html'), 403
  160  
  161  @app.errorhandler(404)
  162  def not_found_error(error):
  163: 	app.logger.exception(error)
  164  	return render_template('static/404.html'), 404
  165  
  166  @app.errorhandler(500)
  167  def internal_error(error):
  168: 	app.logger.exception(error)
  169  	db.session.rollback()
  170  	return render_template('static/500.html'), 500

/Users/Root1/app/app/views/fleet.py:
   92  @app.errorhandler(403)
   93  def forbidden_error(error):
   94: 	app.logger.exception(error)
   95  	return render_template('static/404.html'), 403
   96  
   97  @app.errorhandler(404)
   98  def not_found_error(error):
   99: 	app.logger.exception(error)
  100  	return render_template('static/404.html'), 404
  101  
  102  @app.errorhandler(500)
  103  def internal_error(error):
  104: 	app.logger.exception(error)
  105  	db.session.rollback()
  106  	return render_template('static/500.html'), 500

/Users/Root1/app/app/views/loads.py:
  367  @app.errorhandler(403)
  368  def forbidden_error(error):
  369: 	app.logger.exception(error)
  370  	return render_template('static/404.html'), 403
  371  
  372  @app.errorhandler(404)
  373  def not_found_error(error):
  374: 	app.logger.exception(error)
  375  	return render_template('static/404.html'), 404
  376  
  377  @app.errorhandler(500)
  378  def internal_error(error):
  379: 	app.logger.exception(error)
  380  	db.session.rollback()
  381  	return render_template('static/500.html'), 500

/Users/Root1/app/app/views/static.py:
   61  @app.errorhandler(403)
   62  def forbidden_error(error):
   63: 	app.logger.exception(error)
   64  	return render_template('static/404.html'), 403
   65  
   66  @app.errorhandler(404)
   67  def not_found_error(error):
   68: 	app.logger.exception(error)
   69  	return render_template('static/404.html'), 404
   70  
   71  @app.errorhandler(500)
   72  def internal_error(error):
   73: 	app.logger.exception(error)
   74  	db.session.rollback()
   75  	return render_template('static/500.html'), 500

/Users/Root1/app/app/views/trucks.py:
  286  @app.errorhandler(403)
  287  def forbidden_error(error):
  288: 	app.logger.exception(error)
  289  	return render_template('static/404.html'), 403
  290  
  291  @app.errorhandler(404)
  292  def not_found_error(error):
  293: 	app.logger.exception(error)
  294  	return render_template('static/404.html'), 404
  295  
  296  @app.errorhandler(500)
  297  def internal_error(error):
  298: 	app.logger.exception(error)
  299  	db.session.rollback()
  300  	return render_template('static/500.html'), 500

/Users/Root1/app/venv/bin/sqlformat:
   11  
   12  import sqlparse
   13: from sqlparse.exceptions import SQLParseError
   14  
   15  

/Users/Root1/app/venv/lib/python2.7/site-packages/flask/__init__.py:
   15  # utilities we import from Werkzeug and Jinja2 that are unused
   16  # in the module but are exported as public interface.
   17: from werkzeug.exceptions import abort
   18  from werkzeug.utils import redirect
   19  from jinja2 import Markup, escape

/Users/Root1/app/venv/lib/python2.7/site-packages/flask/app.py:
   19  from werkzeug.datastructures import ImmutableDict
   20  from werkzeug.routing import Map, Rule, RequestRedirect, BuildError
   21: from werkzeug.exceptions import HTTPException, InternalServerError, \
   22       MethodNotAllowed, BadRequest
   23  
   ..
 1064             One can now additionally also register custom exception types
 1065             that do not necessarily have to be a subclass of the
 1066:            :class:`~werkzeug.exceptions.HTTPException` class.
 1067  
 1068          :param code: the code as integer for the handler
 ....
 1353          """This method is called whenever an exception occurs that should be
 1354          handled.  A special case are
 1355:         :class:`~werkzeug.exception.HTTPException`\s which are forwarded by
 1356          this function to the :meth:`handle_http_exception` method.  This
 1357          function will either return a response value or reraise the

/Users/Root1/app/venv/lib/python2.7/site-packages/flask/ctx.py:
   15  from functools import update_wrapper
   16  
   17: from werkzeug.exceptions import HTTPException
   18  
   19  from .globals import _request_ctx_stack, _app_ctx_stack

/Users/Root1/app/venv/lib/python2.7/site-packages/flask/helpers.py:
   27  
   28  from werkzeug.datastructures import Headers
   29: from werkzeug.exceptions import NotFound
   30  
   31  # this was moved in 0.7
   ..
  569      :param directory: the base directory.
  570      :param filename: the untrusted filename relative to that directory.
  571:     :raises: :class:`~werkzeug.exceptions.NotFound` if the resulting path
  572               would fall out of `directory`.
  573      """

/Users/Root1/app/venv/lib/python2.7/site-packages/flask/testsuite/basic.py:
   19  from flask.testsuite import FlaskTestCase, emits_module_deprecation_warning
   20  from flask._compat import text_type
   21: from werkzeug.exceptions import BadRequest, NotFound
   22  from werkzeug.http import parse_date
   23  from werkzeug.routing import BuildError

/Users/Root1/app/venv/lib/python2.7/site-packages/flask/testsuite/blueprints.py:
   15  from flask.testsuite import FlaskTestCase, emits_module_deprecation_warning
   16  from flask._compat import text_type
   17: from werkzeug.exceptions import NotFound
   18  from werkzeug.http import parse_cache_control_header
   19  from jinja2 import TemplateNotFound

/Users/Root1/app/venv/lib/python2.7/site-packages/flask/testsuite/regression.py:
   16  import threading
   17  import unittest
   18: from werkzeug.exceptions import NotFound
   19  from flask.testsuite import FlaskTestCase
   20  

/Users/Root1/app/venv/lib/python2.7/site-packages/flask/wrappers.py:
   11  
   12  from werkzeug.wrappers import Request as RequestBase, Response as ResponseBase
   13: from werkzeug.exceptions import BadRequest
   14  
   15  from .debughelpers import attach_enctype_error_multidict
   ..
   54      #: if matching the URL failed, this is the exception that will be
   55      #: raised / was raised as part of the request handling.  This is
   56:     #: usually a :exc:`~werkzeug.exceptions.NotFound` exception or
   57      #: something similar.
   58      routing_exception = None

/Users/Root1/app/venv/lib/python2.7/site-packages/flask_admin/contrib/mongoengine/view.py:
  512                                error=format_error(ex)),
  513                        'error')
  514:                 log.exception('Failed to create record.')
  515  
  516              return False
  ...
  538                                error=format_error(ex)),
  539                        'error')
  540:                 log.exception('Failed to update record.')
  541  
  542              return False
  ...
  562                                error=format_error(ex)),
  563                        'error')
  564:                 log.exception('Failed to delete record.')
  565  
  566              return False

/Users/Root1/app/venv/lib/python2.7/site-packages/flask_admin/contrib/peewee/view.py:
  356              if not self.handle_view_exception(ex):
  357                  flash(gettext('Failed to create record. %(error)s', error=str(ex)), 'error')
  358:                 log.exception('Failed to create record.')
  359  
  360              return False
  ...
  375              if not self.handle_view_exception(ex):
  376                  flash(gettext('Failed to update record. %(error)s', error=str(ex)), 'error')
  377:                 log.exception('Failed to update record.')
  378  
  379              return False
  ...
  391              if not self.handle_view_exception(ex):
  392                  flash(gettext('Failed to delete record. %(error)s', error=str(ex)), 'error')
  393:                 log.exception('Failed to delete record.')
  394  
  395              return False

/Users/Root1/app/venv/lib/python2.7/site-packages/flask_admin/contrib/pymongo/view.py:
  278              flash(gettext('Failed to create record. %(error)s', error=str(ex)),
  279                    'error')
  280:             log.exception('Failed to create record.')
  281              return False
  282          else:
  ...
  303              flash(gettext('Failed to update record. %(error)s', error=str(ex)),
  304                    'error')
  305:             log.exception('Failed to update record.')
  306              return False
  307          else:
  ...
  329              flash(gettext('Failed to delete record. %(error)s', error=str(ex)),
  330                    'error')
  331:             log.exception('Failed to delete record.')
  332              return False
  333  

/Users/Root1/app/venv/lib/python2.7/site-packages/flask_admin/contrib/rediscli.py:
  207              return self._error('Cli: %s' % err)
  208          except Exception as ex:
  209:             log.exception(ex)
  210              return self._error('Cli: %s' % ex)
  211  

/Users/Root1/app/venv/lib/python2.7/site-packages/flask_admin/contrib/sqla/view.py:
  863              if not self.handle_view_exception(ex):
  864                  flash(gettext('Failed to create record. %(error)s', error=str(ex)), 'error')
  865:                 log.exception('Failed to create record.')
  866  
  867              self.session.rollback()
  ...
  889              if not self.handle_view_exception(ex):
  890                  flash(gettext('Failed to update record. %(error)s', error=str(ex)), 'error')
  891:                 log.exception('Failed to update record.')
  892  
  893              self.session.rollback()
  ...
  915              if not self.handle_view_exception(ex):
  916                  flash(gettext('Failed to delete record. %(error)s', error=str(ex)), 'error')
  917:                 log.exception('Failed to delete record.')
  918  
  919              self.session.rollback()

/Users/Root1/app/venv/lib/python2.7/site-packages/gunicorn-19.1.1.dist-info/DESCRIPTION.rst:
  167    * ``gunicorn.log.error``: rate of error log messages
  168    * ``gunicorn.log.warning``: rate of warning log messages
  169:   * ``gunicorn.log.exception``: rate of exceptional log messages
  170  
  171  To generate new metrics you can `log.info` with a few additional keywords::

/Users/Root1/app/venv/lib/python2.7/site-packages/gunicorn-19.1.1.dist-info/METADATA:
  198    * ``gunicorn.log.error``: rate of error log messages
  199    * ``gunicorn.log.warning``: rate of warning log messages
  200:   * ``gunicorn.log.exception``: rate of exceptional log messages
  201  
  202  To generate new metrics you can `log.info` with a few additional keywords::

/Users/Root1/app/venv/lib/python2.7/site-packages/gunicorn/arbiter.py:
  517              sys.exit(self.APP_LOAD_ERROR)
  518          except:
  519:             self.log.exception("Exception in worker process:\n%s",
  520                      traceback.format_exc())
  521              if not worker.booted:

/Users/Root1/app/venv/lib/python2.7/site-packages/gunicorn/glogging.py:
  222  
  223      def exception(self, msg, *args):
  224:         self.error_log.exception(msg, *args)
  225  
  226      def log(self, lvl, msg, *args, **kwargs):

/Users/Root1/app/venv/lib/python2.7/site-packages/gunicorn/instrument/statsd.py:
   47  
   48      def exception(self, msg, *args, **kwargs):
   49:         Logger.exception(self, msg, *args, **kwargs)
   50:         self.increment("gunicorn.log.exception", 1)
   51  
   52      # Special treatement for info, the most common log level

/Users/Root1/app/venv/lib/python2.7/site-packages/gunicorn/workers/_gaiohttp.py:
   64                  yield from self.wsgi.close()
   65          except:
   66:             self.log.exception('Process shutdown exception')
   67  
   68      @asyncio.coroutine

/Users/Root1/app/venv/lib/python2.7/site-packages/gunicorn/workers/async.py:
   69          except socket.error as e:
   70              if e.args[0] not in (errno.EPIPE, errno.ECONNRESET):
   71:                 self.log.exception("Socket error processing request.")
   72              else:
   73                  if e.args[0] == errno.ECONNRESET:
   ..
  121                  # If the requests have already been sent, we should close the
  122                  # connection to indicate the error.
  123:                 self.log.exception("Error handling request")
  124                  try:
  125                      sock.shutdown(socket.SHUT_RDWR)
  ...
  133                  self.cfg.post_request(self, req, environ, resp)
  134              except Exception:
  135:                 self.log.exception("Exception in post_request hook")
  136          return True
  137  

/Users/Root1/app/venv/lib/python2.7/site-packages/gunicorn/workers/base.py:
  192                            )
  193          else:
  194:             self.log.exception("Error handling request")
  195  
  196              status_int = 500

/Users/Root1/app/venv/lib/python2.7/site-packages/gunicorn/workers/gthread.py:
  271          except socket.error as e:
  272              if e.args[0] not in (errno.EPIPE, errno.ECONNRESET):
  273:                 self.log.exception("Socket error processing request.")
  274              else:
  275                  if e.args[0] == errno.ECONNRESET:
  ...
  328                  # If the requests have already been sent, we should close the
  329                  # connection to indicate the error.
  330:                 self.log.exception("Error handling request")
  331                  try:
  332                      conn.sock.shutdown(socket.SHUT_RDWR)
  ...
  340                  self.cfg.post_request(self, req, environ, resp)
  341              except Exception:
  342:                 self.log.exception("Exception in post_request hook")
  343  
  344          return True

/Users/Root1/app/venv/lib/python2.7/site-packages/gunicorn/workers/sync.py:
  105          except socket.error as e:
  106              if e.args[0] not in (errno.EPIPE, errno.ECONNRESET):
  107:                 self.log.exception("Socket error processing request.")
  108              else:
  109                  if e.args[0] == errno.ECONNRESET:
  ...
  153                  # If the requests have already been sent, we should close the
  154                  # connection to indicate the error.
  155:                 self.log.exception("Error handling request")
  156                  try:
  157                      client.shutdown(socket.SHUT_RDWR)
  ...
  165                  self.cfg.post_request(self, req, environ, resp)
  166              except Exception:
  167:                 self.log.exception("Exception in post_request hook")
  168  

/Users/Root1/app/venv/lib/python2.7/site-packages/jinja2/__init__.py:
   46  
   47  # exceptions
   48: from jinja2.exceptions import TemplateError, UndefinedError, \
   49       TemplateNotFound, TemplatesNotFound, TemplateSyntaxError, \
   50       TemplateAssertionError

/Users/Root1/app/venv/lib/python2.7/site-packages/jinja2/compiler.py:
   15  from jinja2.nodes import EvalContext
   16  from jinja2.visitor import NodeVisitor
   17: from jinja2.exceptions import TemplateAssertionError
   18  from jinja2.utils import Markup, concat, escape
   19  from jinja2._compat import range_type, next, text_type, string_types, \

/Users/Root1/app/venv/lib/python2.7/site-packages/jinja2/debug.py:
   15  from types import TracebackType
   16  from jinja2.utils import missing, internal_code
   17: from jinja2.exceptions import TemplateSyntaxError
   18  from jinja2._compat import iteritems, reraise, code_type
   19  

/Users/Root1/app/venv/lib/python2.7/site-packages/jinja2/environment.py:
   24  from jinja2.compiler import generate
   25  from jinja2.runtime import Undefined, new_context
   26: from jinja2.exceptions import TemplateSyntaxError, TemplateNotFound, \
   27       TemplatesNotFound, TemplateRuntimeError
   28  from jinja2.utils import import_string, LRUCache, Markup, missing, \
   ..
  735              from jinja2.debug import make_traceback as _make_traceback
  736          traceback = _make_traceback(exc_info, source_hint)
  737:         if rendered and self.exception_formatter is not None:
  738:             return self.exception_formatter(traceback)
  739:         if self.exception_handler is not None:
  740:             self.exception_handler(traceback)
  741          exc_type, exc_value, tb = traceback.standard_exc_info
  742          reraise(exc_type, exc_value, tb)

/Users/Root1/app/venv/lib/python2.7/site-packages/jinja2/exceptions.py:
    1  # -*- coding: utf-8 -*-
    2  """
    3:     jinja2.exceptions
    4      ~~~~~~~~~~~~~~~~~
    5  

/Users/Root1/app/venv/lib/python2.7/site-packages/jinja2/ext.py:
   19  from jinja2.environment import Environment
   20  from jinja2.runtime import concat
   21: from jinja2.exceptions import TemplateAssertionError, TemplateSyntaxError
   22  from jinja2.utils import contextfunction, import_string, Markup
   23  from jinja2._compat import next, with_metaclass, string_types, iteritems

/Users/Root1/app/venv/lib/python2.7/site-packages/jinja2/filters.py:
   18       unicode_urlencode
   19  from jinja2.runtime import Undefined
   20: from jinja2.exceptions import FilterArgumentError
   21  from jinja2._compat import next, imap, string_types, text_type, iteritems
   22  

/Users/Root1/app/venv/lib/python2.7/site-packages/jinja2/lexer.py:
   19  from operator import itemgetter
   20  from collections import deque
   21: from jinja2.exceptions import TemplateSyntaxError
   22  from jinja2.utils import LRUCache
   23  from jinja2._compat import next, iteritems, implements_iterator, text_type, \

/Users/Root1/app/venv/lib/python2.7/site-packages/jinja2/loaders.py:
   15  from os import path
   16  from hashlib import sha1
   17: from jinja2.exceptions import TemplateNotFound
   18  from jinja2.utils import open_if_exists, internalcode
   19  from jinja2._compat import string_types, iteritems

/Users/Root1/app/venv/lib/python2.7/site-packages/jinja2/parser.py:
   10  """
   11  from jinja2 import nodes
   12: from jinja2.exceptions import TemplateSyntaxError, TemplateAssertionError
   13  from jinja2.lexer import describe_token, describe_token_expr
   14  from jinja2._compat import next, imap

/Users/Root1/app/venv/lib/python2.7/site-packages/jinja2/runtime.py:
   13  from jinja2.utils import Markup, soft_unicode, escape, missing, concat, \
   14       internalcode, object_type_repr
   15: from jinja2.exceptions import UndefinedError, TemplateRuntimeError, \
   16       TemplateNotFound
   17  from jinja2._compat import next, imap, text_type, iteritems, \

/Users/Root1/app/venv/lib/python2.7/site-packages/jinja2/sandbox.py:
   15  import operator
   16  from jinja2.environment import Environment
   17: from jinja2.exceptions import SecurityError
   18  from jinja2._compat import string_types, function_type, method_type, \
   19       traceback_type, code_type, frame_type, generator_type, PY2

/Users/Root1/app/venv/lib/python2.7/site-packages/jinja2/testsuite/bytecode_cache.py:
   15  from jinja2 import Environment
   16  from jinja2.bccache import FileSystemBytecodeCache
   17: from jinja2.exceptions import TemplateNotFound
   18  
   19  bytecode_cache = FileSystemBytecodeCache()

/Users/Root1/app/venv/lib/python2.7/site-packages/jinja2/testsuite/debug.py:
   40    File ".*?syntaxerror.html", line 4, in (template|<module>)
   41      \{% endif %\}.*?
   42: (jinja2\.exceptions\.)?TemplateSyntaxError: Encountered unknown tag 'endif'. Jinja was looking for the following tags: 'endfor' or 'else'. The innermost block that needs to be closed is 'for'.
   43      ''')
   44  
   ..
   49    File ".*debug.pyc?", line \d+, in test
   50      raise TemplateSyntaxError\('wtf', 42\)
   51: (jinja2\.exceptions\.)?TemplateSyntaxError: wtf
   52    line 42''')
   53  

/Users/Root1/app/venv/lib/python2.7/site-packages/jinja2/testsuite/ext.py:
   15  
   16  from jinja2 import Environment, DictLoader, contextfunction, nodes
   17: from jinja2.exceptions import TemplateAssertionError
   18  from jinja2.ext import Extension
   19  from jinja2.lexer import Token, count_newlines

/Users/Root1/app/venv/lib/python2.7/site-packages/jinja2/testsuite/imports.py:
   14  
   15  from jinja2 import Environment, DictLoader
   16: from jinja2.exceptions import TemplateNotFound, TemplatesNotFound
   17  
   18  

/Users/Root1/app/venv/lib/python2.7/site-packages/jinja2/testsuite/loader.py:
   22  from jinja2._compat import PYPY, PY2
   23  from jinja2.loaders import split_template_path
   24: from jinja2.exceptions import TemplateNotFound
   25  
   26  

/Users/Root1/app/venv/lib/python2.7/site-packages/jinja2/testsuite/security.py:
   17       ImmutableSandboxedEnvironment, unsafe
   18  from jinja2 import Markup, escape
   19: from jinja2.exceptions import SecurityError, TemplateSyntaxError, \
   20       TemplateRuntimeError
   21  from jinja2._compat import text_type

/Users/Root1/app/venv/lib/python2.7/site-packages/migrate/changeset/constraint.py:
    4  from sqlalchemy import schema
    5  
    6: from migrate.exceptions import *
    7  
    8  class ConstraintChangeset(object):

/Users/Root1/app/venv/lib/python2.7/site-packages/migrate/changeset/schema.py:
   15  from sqlalchemy.schema import UniqueConstraint
   16  
   17: from migrate.exceptions import *
   18  from migrate.changeset import SQLA_07, SQLA_08
   19  from migrate.changeset import util

/Users/Root1/app/venv/lib/python2.7/site-packages/migrate/tests/changeset/test_constraint.py:
    6  from sqlalchemy.exc import *
    7  
    8: from migrate.exceptions import *
    9  from migrate.changeset import *
   10  

/Users/Root1/app/venv/lib/python2.7/site-packages/migrate/tests/versioning/test_api.py:
    4  import six
    5  
    6: from migrate.exceptions import *
    7  from migrate.versioning import api
    8  

/Users/Root1/app/venv/lib/python2.7/site-packages/migrate/tests/versioning/test_shell.py:
   10  from sqlalchemy import MetaData, Table
   11  
   12: from migrate.exceptions import *
   13  from migrate.versioning.repository import Repository
   14  from migrate.versioning import genmodel, shell, api

/Users/Root1/app/venv/lib/python2.7/site-packages/migrate/tests/versioning/test_util.py:
    6  from sqlalchemy import *
    7  
    8: from migrate.exceptions import MigrateDeprecationWarning
    9  from migrate.tests import fixture
   10  from migrate.tests.fixture.warnings import catch_warnings

/Users/Root1/app/venv/lib/python2.7/site-packages/migrate/tests/versioning/test_version.py:
    2  # -*- coding: utf-8 -*-
    3  
    4: from migrate.exceptions import *
    5  from migrate.versioning.version import *
    6  

/Users/Root1/app/venv/lib/python2.7/site-packages/migrate/versioning/repository.py:
   88          Ensure the target path is a valid repository.
   89  
   90:         :raises: :exc:`InvalidRepositoryError <migrate.exceptions.InvalidRepositoryError>`
   91          """
   92          # Ensure the existence of required files

/Users/Root1/app/venv/lib/python2.7/site-packages/migrate/versioning/script/base.py:
   35          This version simply ensures the script file's existence
   36  
   37:         :raises: :exc:`InvalidScriptError <migrate.exceptions.InvalidScriptError>`
   38          """
   39          try:

/Users/Root1/app/venv/lib/python2.7/site-packages/migrate/versioning/script/py.py:
   13  from migrate.versioning.script import base
   14  from migrate.versioning.util import import_path, load_model, with_engine
   15: from migrate.exceptions import MigrateDeprecationWarning, InvalidScriptError, ScriptError
   16  import six
   17  from six.moves import StringIO
   ..
   91          :param path: Script location
   92          :type path: string
   93:         :raises: :exc:`InvalidScriptError <migrate.exceptions.InvalidScriptError>`
   94          :returns: Python module
   95          """

/Users/Root1/app/venv/lib/python2.7/site-packages/pbr/core.py:
  108              # been setup - but thats fine, this is a fatal distutils error, so
  109              # being pretty isn't the #1 goal.. being diagnosable is.
  110:             logging.exception('Error parsing')
  111              raise errors.DistutilsSetupError(
  112                  'Error parsing %s: %s: %s' % (path, e.__class__.__name__, e))

/Users/Root1/app/venv/lib/python2.7/site-packages/pip/__init__.py:
   10  import re
   11  
   12: from pip.exceptions import InstallationError, CommandError, PipError
   13  from pip.utils import get_installed_distributions, get_prog
   14  from pip.utils import deprecation
   ..
   17  from pip.commands import get_summaries, get_similar_commands
   18  from pip.commands import commands_dict
   19: from pip._vendor.requests.packages.urllib3.exceptions import (
   20      InsecureRequestWarning,
   21  )

/Users/Root1/app/venv/lib/python2.7/site-packages/pip/_vendor/distlib/locators.py:
  460                      result['digests'][url] = digest
  461          except Exception as e:
  462:             logger.exception('JSON fetch failed: %s', e)
  463          return result
  464  
  ...
  740                  except HTTPError as e:
  741                      if e.code != 404:
  742:                         logger.exception('Fetch failed: %s: %s', url, e)
  743                  except URLError as e:
  744:                     logger.exception('Fetch failed: %s: %s', url, e)
  745                      with self._lock:
  746                          self._bad_hosts.add(host)
  747                  except Exception as e:
  748:                     logger.exception('Fetch failed: %s: %s', url, e)
  749                  finally:
  750                      self._page_cache[url] = result   # even if None (failure)

/Users/Root1/app/venv/lib/python2.7/site-packages/pip/_vendor/distlib/util.py:
  756              result = json.load(reader)
  757      except Exception as e:
  758:         logger.exception('Failed to get external data for %s: %s', url, e)
  759      return result
  760  
  ...
  878                  value = subscriber(event, *args, **kwargs)
  879              except Exception:
  880:                 logger.exception('Exception during event publication')
  881                  value = None
  882              result.append(value)

/Users/Root1/app/venv/lib/python2.7/site-packages/pip/_vendor/distlib/wheel.py:
  648                  return dist
  649              except Exception:  # pragma: no cover
  650:                 logger.exception('installation failed.')
  651                  fileop.rollback()
  652                  raise

/Users/Root1/app/venv/lib/python2.7/site-packages/pip/_vendor/requests/__init__.py:
   61  from .sessions import session, Session
   62  from .status_codes import codes
   63: from .exceptions import (
   64      RequestException, Timeout, URLRequired,
   65      TooManyRedirects, HTTPError, ConnectionError

/Users/Root1/app/venv/lib/python2.7/site-packages/pip/_vendor/requests/adapters.py:
   20                      prepend_scheme_if_needed, get_auth_from_url, urldefragauth)
   21  from .structures import CaseInsensitiveDict
   22: from .packages.urllib3.exceptions import ConnectTimeoutError
   23: from .packages.urllib3.exceptions import HTTPError as _HTTPError
   24: from .packages.urllib3.exceptions import MaxRetryError
   25: from .packages.urllib3.exceptions import ProxyError as _ProxyError
   26: from .packages.urllib3.exceptions import ProtocolError
   27: from .packages.urllib3.exceptions import ReadTimeoutError
   28: from .packages.urllib3.exceptions import SSLError as _SSLError
   29: from .packages.urllib3.exceptions import ResponseError
   30  from .cookies import extract_cookies_to_jar
   31: from .exceptions import (ConnectionError, ConnectTimeout, ReadTimeout, SSLError,
   32                           ProxyError, RetryError)
   33  from .auth import _basic_auth_str

/Users/Root1/app/venv/lib/python2.7/site-packages/pip/_vendor/requests/exceptions.py:
    2  
    3  """
    4: requests.exceptions
    5  ~~~~~~~~~~~~~~~~~~~
    6  
    .
    8  
    9  """
   10: from .packages.urllib3.exceptions import HTTPError as BaseHTTPError
   11  
   12  
   ..
   48  
   49      Catching this error will catch both
   50:     :exc:`~requests.exceptions.ConnectTimeout` and
   51:     :exc:`~requests.exceptions.ReadTimeout` errors.
   52      """
   53  

/Users/Root1/app/venv/lib/python2.7/site-packages/pip/_vendor/requests/models.py:
   20  from .packages.urllib3.filepost import encode_multipart_formdata
   21  from .packages.urllib3.util import parse_url
   22: from .packages.urllib3.exceptions import (
   23      DecodeError, ReadTimeoutError, ProtocolError)
   24: from .exceptions import (
   25      HTTPError, RequestException, MissingSchema, InvalidURL, 
   26      ChunkedEncodingError, ContentDecodingError, ConnectionError, 

/Users/Root1/app/venv/lib/python2.7/site-packages/pip/_vendor/requests/packages/urllib3/connection.py:
   36  
   37  
   38: from .exceptions import (
   39      ConnectTimeoutError,
   40      SystemTimeWarning,

/Users/Root1/app/venv/lib/python2.7/site-packages/pip/_vendor/requests/packages/urllib3/connectionpool.py:
   14  
   15  
   16: from .exceptions import (
   17      ClosedPoolError,
   18      ProtocolError,
   ..
  202          :param timeout:
  203              Seconds to wait before giving up and raising
  204:             :class:`urllib3.exceptions.EmptyPoolError` if the pool is empty and
  205              :prop:`.block` is ``True``.
  206          """
  ...
  435          :param retries:
  436              Configure the number of retries to allow before raising a
  437:             :class:`~urllib3.exceptions.MaxRetryError` exception.
  438  
  439              Pass ``None`` to retry until you receive a response. Pass a

/Users/Root1/app/venv/lib/python2.7/site-packages/pip/_vendor/requests/packages/urllib3/exceptions.py:
   66      :type pool: :class:`~urllib3.connectionpool.HTTPConnectionPool`
   67      :param string url: The requested Url
   68:     :param exceptions.Exception reason: The underlying error
   69  
   70      """

/Users/Root1/app/venv/lib/python2.7/site-packages/pip/_vendor/requests/packages/urllib3/poolmanager.py:
    9  from .connectionpool import HTTPConnectionPool, HTTPSConnectionPool
   10  from .connectionpool import port_by_scheme
   11: from .exceptions import LocationValueError
   12  from .request import RequestMethods
   13  from .util.url import parse_url

/Users/Root1/app/venv/lib/python2.7/site-packages/pip/_vendor/requests/packages/urllib3/response.py:
    4  
    5  from ._collections import HTTPHeaderDict
    6: from .exceptions import ProtocolError, DecodeError, ReadTimeoutError
    7  from .packages.six import string_types as basestring, binary_type
    8  from .connection import HTTPException, BaseSSLError

/Users/Root1/app/venv/lib/python2.7/site-packages/pip/_vendor/requests/packages/urllib3/util/retry.py:
    2  import logging
    3  
    4: from ..exceptions import (
    5      ConnectTimeoutError,
    6      MaxRetryError,
    .
   35          response = http.request('GET', 'http://example.com/', retries=False)
   36  
   37:     Errors will be wrapped in :class:`~urllib3.exceptions.MaxRetryError` unless
   38      retries are disabled, in which case the causing exception will be raised.
   39  

/Users/Root1/app/venv/lib/python2.7/site-packages/pip/_vendor/requests/packages/urllib3/util/ssl_.py:
    2  from hashlib import md5, sha1
    3  
    4: from ..exceptions import SSLError
    5  
    6  

/Users/Root1/app/venv/lib/python2.7/site-packages/pip/_vendor/requests/packages/urllib3/util/timeout.py:
    4  import time
    5  
    6: from ..exceptions import TimeoutStateError
    7  
    8  # A sentinel value to indicate that no timeout was specified by the user in
    .
  170          """ Start the timeout clock, used during a connect() attempt
  171  
  172:         :raises urllib3.exceptions.TimeoutStateError: if you attempt
  173              to start a timer that has been started already.
  174          """
  ...
  183          :return: Elapsed time.
  184          :rtype: float
  185:         :raises urllib3.exceptions.TimeoutStateError: if you attempt
  186              to get duration for a timer that hasn't been started.
  187          """
  ...
  218          If self.total is set, the read timeout is dependent on the amount of
  219          time taken by the connect timeout. If the connection time has not been
  220:         established, a :exc:`~urllib3.exceptions.TimeoutStateError` will be
  221          raised.
  222  
  223          :return: Value to use for the read timeout.
  224          :rtype: int, float, :attr:`Timeout.DEFAULT_TIMEOUT` or None
  225:         :raises urllib3.exceptions.TimeoutStateError: If :meth:`start_connect`
  226              has not yet been called on this object.
  227          """

/Users/Root1/app/venv/lib/python2.7/site-packages/pip/_vendor/requests/packages/urllib3/util/url.py:
    1  from collections import namedtuple
    2  
    3: from ..exceptions import LocationParseError
    4  
    5  

/Users/Root1/app/venv/lib/python2.7/site-packages/pip/_vendor/requests/sessions.py:
   20  from .hooks import default_hooks, dispatch_hook
   21  from .utils import to_key_val_list, default_headers, to_native_string
   22: from .exceptions import (
   23      TooManyRedirects, InvalidSchema, ChunkedEncodingError, ContentDecodingError)
   24  from .packages.urllib3._collections import RecentlyUsedContainer

/Users/Root1/app/venv/lib/python2.7/site-packages/pip/_vendor/requests/utils.py:
   29  from .cookies import RequestsCookieJar, cookiejar_from_dict
   30  from .structures import CaseInsensitiveDict
   31: from .exceptions import InvalidURL
   32  
   33  _hush_pyflakes = (RequestsCookieJar,)

/Users/Root1/app/venv/lib/python2.7/site-packages/pip/basecommand.py:
   14  from pip.locations import running_under_virtualenv
   15  from pip.download import PipSession
   16: from pip.exceptions import (BadCommand, InstallationError, UninstallationError,
   17                              CommandError, PreviousBuildDirError)
   18  from pip.compat import logging_dictConfig

/Users/Root1/app/venv/lib/python2.7/site-packages/pip/commands/help.py:
    2  
    3  from pip.basecommand import Command, SUCCESS
    4: from pip.exceptions import CommandError
    5  
    6  

/Users/Root1/app/venv/lib/python2.7/site-packages/pip/commands/install.py:
   12  from pip.basecommand import Command
   13  from pip.index import PackageFinder
   14: from pip.exceptions import (
   15      InstallationError, CommandError, PreviousBuildDirError,
   16  )

/Users/Root1/app/venv/lib/python2.7/site-packages/pip/commands/list.py:
    5  
    6  from pip.basecommand import Command
    7: from pip.exceptions import DistributionNotFound
    8  from pip.index import PackageFinder
    9  from pip.req import InstallRequirement

/Users/Root1/app/venv/lib/python2.7/site-packages/pip/commands/search.py:
   10  from pip.utils import get_terminal_size
   11  from pip.utils.logging import indent_log
   12: from pip.exceptions import CommandError
   13  from pip.status_codes import NO_MATCHES_FOUND
   14  from pip._vendor import pkg_resources

/Users/Root1/app/venv/lib/python2.7/site-packages/pip/commands/uninstall.py:
    3  from pip.req import InstallRequirement, RequirementSet, parse_requirements
    4  from pip.basecommand import Command
    5: from pip.exceptions import InstallationError
    6  
    7  

/Users/Root1/app/venv/lib/python2.7/site-packages/pip/commands/wheel.py:
    8  from pip.basecommand import Command
    9  from pip.index import PackageFinder
   10: from pip.exceptions import CommandError, PreviousBuildDirError
   11  from pip.req import InstallRequirement, RequirementSet, parse_requirements
   12  from pip.utils import normalize_path

/Users/Root1/app/venv/lib/python2.7/site-packages/pip/commands/zip.py:
   13  from pip.utils.deprecation import RemovedInPip7Warning
   14  from pip.utils.logging import indent_log
   15: from pip.exceptions import InstallationError
   16  from pip.basecommand import Command
   17  

/Users/Root1/app/venv/lib/python2.7/site-packages/pip/download.py:
   20  import pip
   21  
   22: from pip.exceptions import InstallationError, HashMismatch
   23  from pip.models import PyPI
   24  from pip.utils import (splitext, rmtree, format_size, display_path,

/Users/Root1/app/venv/lib/python2.7/site-packages/pip/index.py:
   18  from pip.utils.deprecation import RemovedInPip7Warning, RemovedInPip8Warning
   19  from pip.utils.logging import indent_log
   20: from pip.exceptions import (
   21      DistributionNotFound, BestVersionAlreadyInstalled, InvalidWheelFilename,
   22      UnsupportedWheel,
   ..
   29  from pip._vendor import html5lib, requests, pkg_resources, six
   30  from pip._vendor.packaging.version import parse as parse_version
   31: from pip._vendor.requests.exceptions import SSLError
   32  
   33  

/Users/Root1/app/venv/lib/python2.7/site-packages/pip/req/req_install.py:
   22  from pip.compat import native_str, WINDOWS
   23  from pip.download import is_url, url_to_path, path_to_url, is_archive_file
   24: from pip.exceptions import (
   25      InstallationError, UninstallationError, UnsupportedWheel,
   26  )

/Users/Root1/app/venv/lib/python2.7/site-packages/pip/req/req_set.py:
    8  
    9  from pip.download import (url_to_path, unpack_url)
   10: from pip.exceptions import (InstallationError, BestVersionAlreadyInstalled,
   11                              DistributionNotFound, PreviousBuildDirError)
   12  from pip.locations import (PIP_DELETE_MARKER_FILENAME, build_prefix)

/Users/Root1/app/venv/lib/python2.7/site-packages/pip/req/req_uninstall.py:
    8  
    9  from pip.compat import uses_pycache, WINDOWS
   10: from pip.exceptions import UninstallationError
   11  from pip.utils import (rmtree, ask, is_local, dist_is_local, renames,
   12                         normalize_path)

/Users/Root1/app/venv/lib/python2.7/site-packages/pip/utils/__init__.py:
   14  import zipfile
   15  
   16: from pip.exceptions import InstallationError, BadCommand
   17  from pip.compat import console_to_str, stdlib_pkgs
   18  from pip.locations import (

/Users/Root1/app/venv/lib/python2.7/site-packages/pip/vcs/__init__.py:
    8  from pip._vendor.six.moves.urllib import parse as urllib_parse
    9  
   10: from pip.exceptions import BadCommand
   11  from pip.utils import (display_path, backup_dir, find_command,
   12                         rmtree, ask_path_exists)

/Users/Root1/app/venv/lib/python2.7/site-packages/pip/vcs/subversion.py:
  165  
  166      def _get_svn_url_rev(self, location):
  167:         from pip.exceptions import InstallationError
  168  
  169          with open(os.path.join(location, self.dirname, 'entries')) as f:

/Users/Root1/app/venv/lib/python2.7/site-packages/pip/wheel.py:
   20  from pip._vendor.six import StringIO
   21  
   22: from pip.exceptions import InvalidWheelFilename, UnsupportedWheel
   23  from pip.locations import distutils_scheme
   24  from pip import pep425tags

/Users/Root1/app/venv/lib/python2.7/site-packages/pytz-2014.10.dist-info/DESCRIPTION.rst:
  210  
  211  If ``is_dst`` is not specified, ambiguous timestamps will raise
  212: an ``pytz.exceptions.AmbiguousTimeError`` exception.
  213  
  214  >>> tz.utcoffset(normal)
  ...
  219  'NDT'
  220  
  221: >>> import pytz.exceptions
  222  >>> try:
  223  ...     tz.utcoffset(ambiguous)
  224: ... except pytz.exceptions.AmbiguousTimeError:
  225: ...     print('pytz.exceptions.AmbiguousTimeError: %s' % ambiguous)
  226: pytz.exceptions.AmbiguousTimeError: 2009-10-31 23:30:00
  227  >>> try:
  228  ...     tz.dst(ambiguous)
  229: ... except pytz.exceptions.AmbiguousTimeError:
  230: ...     print('pytz.exceptions.AmbiguousTimeError: %s' % ambiguous)
  231: pytz.exceptions.AmbiguousTimeError: 2009-10-31 23:30:00
  232  >>> try:
  233  ...     tz.tzname(ambiguous)
  234: ... except pytz.exceptions.AmbiguousTimeError:
  235: ...     print('pytz.exceptions.AmbiguousTimeError: %s' % ambiguous)
  236: pytz.exceptions.AmbiguousTimeError: 2009-10-31 23:30:00
  237  
  238  
  ...
  320  >>> try:
  321  ...     eastern.localize(dt, is_dst=None)
  322: ... except pytz.exceptions.AmbiguousTimeError:
  323: ...     print('pytz.exceptions.AmbiguousTimeError: %s' % dt)
  324: pytz.exceptions.AmbiguousTimeError: 2002-10-27 01:30:00
  325  
  326  Similarly, 2:30am on 7th April 2002 never happened at all in the
  ...
  331  >>> try:
  332  ...     eastern.localize(dt, is_dst=None)
  333: ... except pytz.exceptions.NonExistentTimeError:
  334: ...     print('pytz.exceptions.NonExistentTimeError: %s' % dt)
  335: pytz.exceptions.NonExistentTimeError: 2002-04-07 02:30:00
  336  
  337  Both of these exceptions share a common base class to make error handling

/Users/Root1/app/venv/lib/python2.7/site-packages/pytz-2014.10.dist-info/METADATA:
  230  
  231  If ``is_dst`` is not specified, ambiguous timestamps will raise
  232: an ``pytz.exceptions.AmbiguousTimeError`` exception.
  233  
  234  >>> tz.utcoffset(normal)
  ...
  239  'NDT'
  240  
  241: >>> import pytz.exceptions
  242  >>> try:
  243  ...     tz.utcoffset(ambiguous)
  244: ... except pytz.exceptions.AmbiguousTimeError:
  245: ...     print('pytz.exceptions.AmbiguousTimeError: %s' % ambiguous)
  246: pytz.exceptions.AmbiguousTimeError: 2009-10-31 23:30:00
  247  >>> try:
  248  ...     tz.dst(ambiguous)
  249: ... except pytz.exceptions.AmbiguousTimeError:
  250: ...     print('pytz.exceptions.AmbiguousTimeError: %s' % ambiguous)
  251: pytz.exceptions.AmbiguousTimeError: 2009-10-31 23:30:00
  252  >>> try:
  253  ...     tz.tzname(ambiguous)
  254: ... except pytz.exceptions.AmbiguousTimeError:
  255: ...     print('pytz.exceptions.AmbiguousTimeError: %s' % ambiguous)
  256: pytz.exceptions.AmbiguousTimeError: 2009-10-31 23:30:00
  257  
  258  
  ...
  340  >>> try:
  341  ...     eastern.localize(dt, is_dst=None)
  342: ... except pytz.exceptions.AmbiguousTimeError:
  343: ...     print('pytz.exceptions.AmbiguousTimeError: %s' % dt)
  344: pytz.exceptions.AmbiguousTimeError: 2002-10-27 01:30:00
  345  
  346  Similarly, 2:30am on 7th April 2002 never happened at all in the
  ...
  351  >>> try:
  352  ...     eastern.localize(dt, is_dst=None)
  353: ... except pytz.exceptions.NonExistentTimeError:
  354: ...     print('pytz.exceptions.NonExistentTimeError: %s' % dt)
  355: pytz.exceptions.NonExistentTimeError: 2002-04-07 02:30:00
  356  
  357  Both of these exceptions share a common base class to make error handling

/Users/Root1/app/venv/lib/python2.7/site-packages/pytz/__init__.py:
   31      resource_stream = None
   32  
   33: from pytz.exceptions import AmbiguousTimeError
   34: from pytz.exceptions import InvalidTimeError
   35: from pytz.exceptions import NonExistentTimeError
   36: from pytz.exceptions import UnknownTimeZoneError
   37  from pytz.lazy import LazyDict, LazyList, LazySet
   38  from pytz.tzinfo import unpickler

/Users/Root1/app/venv/lib/python2.7/site-packages/pytz/tzinfo.py:
    9  
   10  import pytz
   11: from pytz.exceptions import AmbiguousTimeError, NonExistentTimeError
   12  
   13  __all__ = []

/Users/Root1/app/venv/lib/python2.7/site-packages/requests/__init__.py:
   28  from .sessions import session, Session
   29  from .status_codes import codes
   30: from .exceptions import (
   31      RequestException, Timeout, URLRequired,
   32      TooManyRedirects, HTTPError, ConnectionError

/Users/Root1/app/venv/lib/python2.7/site-packages/requests/exceptions.py:
    2  
    3  """
    4: requests.exceptions
    5  ~~~~~~~~~~~~~~~~~~~
    6  

/Users/Root1/app/venv/lib/python2.7/site-packages/requests/models.py:
   18  from .auth import HTTPBasicAuth, HTTPProxyAuth
   19  from .cookies import cookiejar_from_dict, extract_cookies_to_jar, get_cookie_header
   20: from .packages.urllib3.exceptions import MaxRetryError, LocationParseError
   21: from .packages.urllib3.exceptions import SSLError as _SSLError
   22: from .packages.urllib3.exceptions import HTTPError as _HTTPError
   23  from .packages.urllib3 import connectionpool, poolmanager
   24  from .packages.urllib3.filepost import encode_multipart_formdata
   25  from .defaults import SCHEMAS
   26: from .exceptions import (
   27      ConnectionError, HTTPError, RequestException, Timeout, TooManyRedirects,
   28      URLRequired, SSLError, MissingSchema, InvalidSchema, InvalidURL)

/Users/Root1/app/venv/lib/python2.7/site-packages/requests/packages/urllib3/connectionpool.py:
   43  from .response import HTTPResponse
   44  from .util import get_host, is_connection_dropped
   45: from .exceptions import (
   46      EmptyPoolError,
   47      HostChangedError,
   ..
  200          :param timeout:
  201              Seconds to wait before giving up and raising
  202:             :class:`urllib3.exceptions.EmptyPoolError` if the pool is empty and
  203              :prop:`.block` is ``True``.
  204          """

/Users/Root1/app/venv/lib/python2.7/site-packages/requests/packages/urllib3/poolmanager.py:
   10  from .connectionpool import HTTPConnectionPool, HTTPSConnectionPool
   11  from .connectionpool import get_host, connection_from_url, port_by_scheme
   12: from .exceptions import HostChangedError
   13  from .request import RequestMethods
   14  

/Users/Root1/app/venv/lib/python2.7/site-packages/requests/packages/urllib3/response.py:
   11  from io import BytesIO
   12  
   13: from .exceptions import HTTPError
   14  from .packages.six import string_types as basestring
   15  

/Users/Root1/app/venv/lib/python2.7/site-packages/requests/packages/urllib3/util.py:
   18  
   19  from .packages import six
   20: from .exceptions import LocationParseError
   21  
   22  

/Users/Root1/app/venv/lib/python2.7/site-packages/requests/safe_mode.py:
   14  from .models import Response
   15  from .packages.urllib3.response import HTTPResponse
   16: from .exceptions import RequestException, ConnectionError, HTTPError
   17  import socket
   18  

/Users/Root1/app/venv/lib/python2.7/site-packages/sqlalchemy/engine/base.py:
 1074          exc_info = sys.exc_info()
 1075  
 1076:         if context and context.exception is None:
 1077:             context.exception = e
 1078  
 1079          if not self._is_disconnect:
 ....
 1247  
 1248  class ExceptionContextImpl(ExceptionContext):
 1249:     """Implement the :class:`.ExceptionContext` interface."""
 1250  
 1251      def __init__(self, exception, sqlalchemy_exception,

/Users/Root1/app/venv/lib/python2.7/site-packages/sqlalchemy/engine/interfaces.py:
  740      .. seealso::
  741  
  742:         :attr:`.ExecutionContext.exception`
  743  
  744          :meth:`.ConnectionEvents.dbapi_error`
  ...
  964      could be constructed.
  965  
  966:     Note that the :attr:`.ExceptionContext.statement` and
  967:     :attr:`.ExceptionContext.parameters` members may represent a
  968      different value than that of the :class:`.ExecutionContext`,
  969      potentially in the case where a

/Users/Root1/app/venv/lib/python2.7/site-packages/sqlalchemy/events.py:
  672          as well as to allow extensibility of the event without backwards
  673          incompatibility, the sole argument received is an instance of
  674:         :class:`.ExceptionContext`.   This object contains data members
  675          representing detail about the exception.
  676  
  ...
  708          function.  In this case, event handling will continue onto the
  709          next handler.   The "chained" exception is available using
  710:         :attr:`.ExceptionContext.chained_exception`::
  711  
  712              @event.listens_for(Engine, "handle_error", retval=True)
  ...
  729          exceptions raised within the autoflush process.
  730  
  731:         :param context: an :class:`.ExceptionContext` object.  See this
  732           class for details on all available members.
  733  

/Users/Root1/app/venv/lib/python2.7/site-packages/sqlparse/__init__.py:
   16  
   17  # Deprecated in 0.1.5. Will be removed in 0.2.0
   18: from sqlparse.exceptions import SQLParseError
   19  
   20  

/Users/Root1/app/venv/lib/python2.7/site-packages/sqlparse/formatter.py:
    7  
    8  from sqlparse import filters
    9: from sqlparse.exceptions import SQLParseError
   10  
   11  

/Users/Root1/app/venv/lib/python2.7/site-packages/stripe/http_client.py:
  116              status_code = result.status_code
  117          except Exception, e:
  118:             # Would catch just requests.exceptions.RequestException, but can
  119              # also raise ValueError, RuntimeError, etc.
  120              self._handle_request_error(e)
  ...
  122  
  123      def _handle_request_error(self, e):
  124:         if isinstance(e, requests.exceptions.RequestException):
  125              msg = ("Unexpected error communicating with Stripe.  "
  126                     "If this problem persists, let us know at "

/Users/Root1/app/venv/lib/python2.7/site-packages/stripe/test/test_http_client.py:
  121  
  122      def mock_error(self, mock):
  123:         mock.exceptions.RequestException = Exception
  124:         mock.request.side_effect = mock.exceptions.RequestException()
  125  
  126      def check_call(self, mock, meth, url, post_data, headers):

/Users/Root1/app/venv/lib/python2.7/site-packages/werkzeug/__init__.py:
   47                               'run_wsgi_app'],
   48      'werkzeug.testapp':     ['test_app'],
   49:     'werkzeug.exceptions':  ['abort', 'Aborter'],
   50      'werkzeug.urls':        ['url_decode', 'url_encode', 'url_quote',
   51                               'url_quote_plus', 'url_unquote',
   ..
  152  # Due to bootstrapping issues we need to import exceptions here.
  153  # Don't ask :-(
  154: __import__('werkzeug.exceptions')
  155  

/Users/Root1/app/venv/lib/python2.7/site-packages/werkzeug/contrib/wrappers.py:
   27      from json import loads
   28  
   29: from werkzeug.exceptions import BadRequest
   30  from werkzeug.utils import cached_property
   31  from werkzeug.http import dump_options_header, parse_options_header
   ..
   46      through simplejson if possible.
   47  
   48:     :exc:`~werkzeug.exceptions.BadRequest` will be raised if the content-type
   49      is not json or if the data itself cannot be parsed as json.
   50      """
   ..
   65      input data through `protobuf`_ if possible.
   66  
   67:     :exc:`~werkzeug.exceptions.BadRequest` will be raised if the content-type
   68      is not protobuf or if the data itself cannot be parsed property.
   69  
   ..
   72  
   73      #: by default the :class:`ProtobufRequestMixin` will raise a
   74:     #: :exc:`~werkzeug.exceptions.BadRequest` if the object is not
   75      #: initialized.  You can bypass that check by setting this
   76      #: attribute to `False`.

/Users/Root1/app/venv/lib/python2.7/site-packages/werkzeug/debug/tbtools.py:
  208          else:
  209              exception_type = exc_type
  210:         self.exception_type = exception_type
  211  
  212          # we only add frames to the list that are not hidden.  This follows
  213:         # the the magic variables as defined by paste.exceptions.collector
  214          self.frames = []
  215          while tb:
  ...
  325              'title':        title and u'<h3>%s</h3>' % title or u'',
  326              'frames':       u'\n'.join(frames),
  327:             'description':  description_wrapper % escape(self.exception)
  328          }
  329  
  330      def render_full(self, evalex=False, secret=None):
  331          """Render the Full HTML page with the traceback info."""
  332:         exc = escape(self.exception)
  333          return PAGE_HTML % {
  334              'evalex':           evalex and 'true' or 'false',
  ...
  336              'title':            exc,
  337              'exception':        exc,
  338:             'exception_type':   escape(self.exception_type),
  339              'summary':          self.render_summary(include_title=False),
  340              'plaintext':        self.plaintext,
  ...
  354              )
  355              yield u'    ' + frame.current_line.strip()
  356:         yield self.exception
  357  
  358      def plaintext(self):

/Users/Root1/app/venv/lib/python2.7/site-packages/werkzeug/exceptions.py:
    1  # -*- coding: utf-8 -*-
    2  """
    3:     werkzeug.exceptions
    4      ~~~~~~~~~~~~~~~~~~~
    5  
    .
   15          from werkzeug.wrappers import BaseRequest
   16          from werkzeug.wsgi import responder
   17:         from werkzeug.exceptions import HTTPException, NotFound
   18  
   19          def view(request):
   ..
   63  # onto our parent module.
   64  import werkzeug
   65: werkzeug.exceptions = sys.modules[__name__]
   66  
   67  from werkzeug._internal import _get_environ

/Users/Root1/app/venv/lib/python2.7/site-packages/werkzeug/routing.py:
  102  from werkzeug.urls import url_encode, url_quote, url_join
  103  from werkzeug.utils import redirect, format_string
  104: from werkzeug.exceptions import HTTPException, NotFound, MethodNotAllowed
  105  from werkzeug._internal import _get_environ, _encode_idna
  106  from werkzeug._compat import itervalues, iteritems, to_unicode, to_bytes, \
  ...
 1301            matching.  A `NotFound` exception is also a WSGI application you
 1302            can call to get a default page not found page (happens to be the
 1303:           same object as `werkzeug.exceptions.NotFound`)
 1304  
 1305          - you receive a `MethodNotAllowed` exception that indicates that there

/Users/Root1/app/venv/lib/python2.7/site-packages/werkzeug/serving.py:
   62       wsgi_encoding_dance
   63  from werkzeug.urls import url_parse, url_unquote
   64: from werkzeug.exceptions import InternalServerError, BadRequest
   65  
   66  

/Users/Root1/app/venv/lib/python2.7/site-packages/werkzeug/testsuite/contrib/cache.py:
   21      import redis
   22      try:
   23:         from redis.exceptions import ConnectionError as RedisConnectionError
   24          cache.RedisCache(key_prefix='werkzeug-test-case:')._client.set('test','connection')
   25      except RedisConnectionError:

/Users/Root1/app/venv/lib/python2.7/site-packages/werkzeug/testsuite/datastructures.py:
   28       iterlistvalues, text_type, PY2
   29  from werkzeug.testsuite import WerkzeugTestCase
   30: from werkzeug.exceptions import BadRequestKeyError
   31  
   32  

/Users/Root1/app/venv/lib/python2.7/site-packages/werkzeug/testsuite/exceptions.py:
    1  # -*- coding: utf-8 -*-
    2  """
    3:     werkzeug.testsuite.exceptions
    4      ~~~~~~~~~~~~~~~~~~~~~~~~~~~~~
    5  

/Users/Root1/app/venv/lib/python2.7/site-packages/werkzeug/testsuite/formparser.py:
   20  from werkzeug.test import create_environ, Client
   21  from werkzeug.wrappers import Request, Response
   22: from werkzeug.exceptions import RequestEntityTooLarge
   23  from werkzeug.datastructures import MultiDict
   24  from werkzeug.formparser import parse_form_data

/Users/Root1/app/venv/lib/python2.7/site-packages/werkzeug/testsuite/wrappers.py:
   18  
   19  from werkzeug import wrappers
   20: from werkzeug.exceptions import SecurityError
   21  from werkzeug.wsgi import LimitedStream
   22  from werkzeug.datastructures import MultiDict, ImmutableOrderedMultiDict, \

/Users/Root1/app/venv/lib/python2.7/site-packages/werkzeug/testsuite/wsgi.py:
   16  
   17  from werkzeug.wrappers import BaseResponse
   18: from werkzeug.exceptions import BadRequest, ClientDisconnected
   19  from werkzeug.test import Client, create_environ, run_wsgi_app
   20  from werkzeug import wsgi

/Users/Root1/app/venv/lib/python2.7/site-packages/werkzeug/utils.py:
  569      def __init__(self, import_name, exception):
  570          self.import_name = import_name
  571:         self.exception = exception
  572  
  573          msg = (
  ...
  599      def __repr__(self):
  600          return '<%s(%r, %r)>' % (self.__class__.__name__, self.import_name,
  601:                                  self.exception)
  602  
  603  

/Users/Root1/app/venv/lib/python2.7/site-packages/werkzeug/wrappers.py:
  141      #: :attr:`form` or :attr:`files` attribute is accessed and the
  142      #: parsing fails because more than the specified value is transmitted
  143:     #: a :exc:`~werkzeug.exceptions.RequestEntityTooLarge` exception is raised.
  144      #:
  145      #: Have a look at :ref:`dealing-with-request-data` for more details.
  ...
  152      #: :attr:`form` or :attr:`files` attribute is accessed and the
  153      #: data in memory for post data is longer than the specified value a
  154:     #: :exc:`~werkzeug.exceptions.RequestEntityTooLarge` exception is raised.
  155      #:
  156      #: Have a look at :ref:`dealing-with-request-data` for more details.

/Users/Root1/app/venv/lib/python2.7/site-packages/werkzeug/wsgi.py:
   59      This optionally it verifies that the host is in a list of trusted hosts.
   60      If the host is not in there it will raise a
   61:     :exc:`~werkzeug.exceptions.SecurityError`.
   62  
   63      Note that the string returned might contain unicode characters as the
   ..
  133      of the `X-Forwarded-Host` header.  Optionally it verifies that the host
  134      is in a list of trusted hosts.  If the host is not in there it will raise
  135:     a :exc:`~werkzeug.exceptions.SecurityError`.
  136  
  137      :param environ: the WSGI environment to get the host of.
  ...
  150      if trusted_hosts is not None:
  151          if not host_is_trusted(rv, trusted_hosts):
  152:             from werkzeug.exceptions import SecurityError
  153              raise SecurityError('Host "%s" is not trusted' % rv)
  154      return rv
  ...
  956          value of this function is returned from read functions in case
  957          the client went away.  By default a
  958:         :exc:`~werkzeug.exceptions.ClientDisconnected` exception is raised.
  959          """
  960:         from werkzeug.exceptions import ClientDisconnected
  961          raise ClientDisconnected()
  962  

266 matches across 138 files


Searching 17190 files for "app.logger.info"

/Users/Root1/app/app/__init__.py:
   58      app.logger.addHandler(file_handler)
   59      app.logger.setLevel(logging.INFO)
   60:     app.logger.info('TMS startup')
   61  
   62  if os.environ.get('HEROKU') is not None:
   ..
   65      app.logger.addHandler(stream_handler)
   66      app.logger.setLevel(logging.INFO)
   67:     app.logger.info('TMS startup')
   68  
   69  # Function to easily find your assets

/Users/Root1/app/app/controllers/LoadService.py:
   72  										location.state.data,
   73  										location.postal_code.data)
   74: 		app.logger.info('test')
   75  		if(location.pickup_weight.data.strip('\t\n\r') is not None):
   76: 			app.logger.info('creating pickup')
   77  			pickup_detail = LoadDetailFactory(location.pickup_weight.data, location.pickup_notes.data, "Pickup")
   78  		if(location.delivery_weight.data.strip('\t\n\r') is not None):
   79: 			app.logger.info('creating delivery')
   80  			delivery_detail = LoadDetailFactory(location.delivery_weight.data, location.delivery_notes.data, "Delivery")
   81  		contact = ContactFactory(location.contact_name.data, location.contact_phone.data, location.contact_email.data)

/Users/Root1/app/app/emails.py:
   22  
   23  def register_account(user):
   24: 	app.logger.info("Sending email to %s" % user.email)
   25  	s = get_serializer()
   26  
   ..
   40  
   41  def reset_pass(user):
   42: 	app.logger.info("Sending email to %s" % user.email)
   43  	s = get_serializer()
   44  
   ..
   59  
   60  def new_lead(email):
   61: 	app.logger.info("Sending new lead email!")
   62  
   63  	send_email("New Lead Notification",
   ..
   70  
   71  def contact_us(form):
   72: 	app.logger.info("Sending contact us email!")
   73  
   74  	send_email(form.subject.data,
   ..
   85  
   86  def request_demo(form):
   87: 	app.logger.info("Sending request demo email!")
   88  
   89  	send_email("Demo Requested",
   ..
  106  
  107  def ping_driver(driver):
  108: 	app.logger.info("Sending driver check-in email!")
  109  
  110  	s = get_serializer()

/Users/Root1/app/app/views/auth.py:
   66  		register_account(user)
   67  		flash("A registration e-mail has been sent to %s" % register_form.email.data)
   68: 		app.logger.info("User \"%s\" with role \"%s\" created" % (user.email, user.roles[0].name))
   69  	if forgot_form.validate_on_submit():
   70  		user = User.query.filter_by(email=forgot_form.email.data).first()
   71: 		app.logger.info("User \"%s\" requested a password reset" % user.email)
   72  		reset_pass(user)
   73  		flash("Password reset instrunctions have been sent to %s" % forgot_form.email.data)
   ..
  115  		register_account(user)
  116  		flash("A registration e-mail has been sent to %s" % register_form.email.data)
  117: 		app.logger.info("User \"%s\" with role \"%s\" created" % (user.email, user.roles[0].name))
  118  		return redirect(url_for('.login'))
  119  	return redirect(url_for('.login', type='register'))
  ...
  149      try:
  150      	user_id = s.loads(activation_slug)
  151:     	app.logger.info("User %s" % user_id)
  152      except BadSignature:
  153      	abort(404)
  ...
  157      db.session.add(user)
  158      db.session.commit()
  159:     app.logger.info("User \"%s\" is now activated" % user.email)
  160      flash('Your account is now activated. Please log in.')
  161      return redirect(url_for('.login'))
  ...
  181  		user = User.query.get_or_404(user_id)
  182  		login_user(user, remember=False)
  183: 		app.logger.info("User \"%s\"'s password is now reset" % user.email)
  184  		flash('Your password has been reset. Please create a new password.')
  185  
  ...
  210  @app.errorhandler(500)
  211  def internal_error(error):
  212: 	app.logger.info(error)
  213  	db.session.rollback()
  214  	return render_template('static/500.html', error=error), 500

/Users/Root1/app/app/views/loads.py:
  175  
  176  			latitude = js["results"][0]["geometry"]["location"]["lat"]
  177: 			app.logger.info(latitude)
  178  			longitude = js["results"][0]["geometry"]["location"]["lng"]
  179: 			app.logger.info(longitude)
  180  			if(form.pickup_weight.data.strip('\t\n\r') != ""):
  181: 				app.logger.info('creating pickup')
  182  				pickup_detail = LoadDetailFactory(form.pickup_weight.data, form.pickup_notes.data, "Pickup")
  183  			else:
  184  				pickup_detail = None
  185  			if(form.delivery_weight.data.strip('\t\n\r') != ""):
  186: 				app.logger.info('creating delivery')
  187  				delivery_detail = LoadDetailFactory(form.delivery_weight.data, form.delivery_notes.data, "Delivery")
  188  			else:

/Users/Root1/app/app/views/trucks.py:
   76  			truck.name = form.name.data
   77  			for locationData in form.locations:
   78: 				app.logger.info("%s - %s" % (locationData.location_id.data, locationData.stop_number.data))
   79  				location = Location.query.get(int(locationData.location_id.data))
   80  				location.stop_number = int(locationData.stop_number.data)
   81: 				app.logger.info("%s - %s" % (location.address.postal_code, location.stop_number))
   82  				db.session.add(location)
   83  			#carrier.latitude = form.latitude.data
   ..
  186  	try:
  187  		driver_id = s.loads(activation_slug)
  188: 		app.logger.info("Truck %s" % driver_id)
  189  	except BadSignature:
  190  		abort(404)
  ...
  349  	for load in truck.loads:
  350  		for location in load.lane.locations:
  351: 			app.logger.info("%s, %s" % (location.stop_number, int(location.stop_number) == 1))
  352  
  353  			if int(location.stop_number) == 1:
  354: 				app.logger.info("returning %s" % location.stop_number)
  355  				return location
  356  	return None

27 matches across 6 files


Searching 17190 files for "app.logger.exception"

/Users/Root1/app/app/emails.py:
   13  			mail.send(msg)
   14  	except Exception, e:
   15: 		app.logger.exception(e)
   16  
   17  def send_email(subject, sender, recipients, text_body, html_body):
   ..
   48  		user_id = s.loads(activation_slug)
   49  	except BadSignature:
   50: 		app.logger.exception(error)
   51  		abort(404)
   52  	send_email("Password Reset",
   ..
  115  		driver_id = s.loads(activation_slug)
  116  	except BadSignature:
  117: 		app.logger.exception(error)
  118  		abort(404)
  119  

/Users/Root1/app/app/views/auth.py:
  200  @app.errorhandler(403)
  201  def forbidden_error(error):
  202: 	app.logger.exception(error)
  203  	return render_template('static/404.html'), 403
  204  
  205  @app.errorhandler(404)
  206  def not_found_error(error):
  207: 	app.logger.exception(error)
  208  	return render_template('static/404.html'), 404
  209  

/Users/Root1/app/app/views/drivers.py:
  156  @app.errorhandler(403)
  157  def forbidden_error(error):
  158: 	app.logger.exception(error)
  159  	return render_template('static/404.html'), 403
  160  
  161  @app.errorhandler(404)
  162  def not_found_error(error):
  163: 	app.logger.exception(error)
  164  	return render_template('static/404.html'), 404
  165  
  166  @app.errorhandler(500)
  167  def internal_error(error):
  168: 	app.logger.exception(error)
  169  	db.session.rollback()
  170  	return render_template('static/500.html'), 500

/Users/Root1/app/app/views/fleet.py:
   92  @app.errorhandler(403)
   93  def forbidden_error(error):
   94: 	app.logger.exception(error)
   95  	return render_template('static/404.html'), 403
   96  
   97  @app.errorhandler(404)
   98  def not_found_error(error):
   99: 	app.logger.exception(error)
  100  	return render_template('static/404.html'), 404
  101  
  102  @app.errorhandler(500)
  103  def internal_error(error):
  104: 	app.logger.exception(error)
  105  	db.session.rollback()
  106  	return render_template('static/500.html'), 500

/Users/Root1/app/app/views/loads.py:
  367  @app.errorhandler(403)
  368  def forbidden_error(error):
  369: 	app.logger.exception(error)
  370  	return render_template('static/404.html'), 403
  371  
  372  @app.errorhandler(404)
  373  def not_found_error(error):
  374: 	app.logger.exception(error)
  375  	return render_template('static/404.html'), 404
  376  
  377  @app.errorhandler(500)
  378  def internal_error(error):
  379: 	app.logger.exception(error)
  380  	db.session.rollback()
  381  	return render_template('static/500.html'), 500

/Users/Root1/app/app/views/static.py:
   61  @app.errorhandler(403)
   62  def forbidden_error(error):
   63: 	app.logger.exception(error)
   64  	return render_template('static/404.html'), 403
   65  
   66  @app.errorhandler(404)
   67  def not_found_error(error):
   68: 	app.logger.exception(error)
   69  	return render_template('static/404.html'), 404
   70  
   71  @app.errorhandler(500)
   72  def internal_error(error):
   73: 	app.logger.exception(error)
   74  	db.session.rollback()
   75  	return render_template('static/500.html'), 500

/Users/Root1/app/app/views/trucks.py:
  286  @app.errorhandler(403)
  287  def forbidden_error(error):
  288: 	app.logger.exception(error)
  289  	return render_template('static/404.html'), 403
  290  
  291  @app.errorhandler(404)
  292  def not_found_error(error):
  293: 	app.logger.exception(error)
  294  	return render_template('static/404.html'), 404
  295  
  296  @app.errorhandler(500)
  297  def internal_error(error):
  298: 	app.logger.exception(error)
  299  	db.session.rollback()
  300  	return render_template('static/500.html'), 500

20 matches across 7 files
